Workbook
Name Air_Freight_Result_LU: #REF!
Name Air_Frieght_Unique_Names: #REF!
Name Alien: #REF!
Name Calcs_Lookup: #REF!
Name Calculations: #REF!
Name Category: #REF!
Name Chilled: #REF!
Name CO2perGJ_jet: #REF!
Name Cooking_Results_LU: #REF!
Name Cooking_Unique_Name: #REF!
Name DB_DG_Col2: #REF!
Name DB_DG_Start2: #REF!
Name DB_Lookup: #REF!
Name DomRefrig_Results_LU: #REF!
Name DomRefrig_Unique: #REF!
Name EF_custom: #REF!
Name Ef_for_km: #REF!
Name Ef_for_mile: #REF!
Name Eol_Qs_LU: #REF!
Name EOL_Region_LU: #REF!
Name EOL_Results_LU: #REF!
Name EOL_Unique: #REF!
Name EOL_Unique_Name: #REF!
Name EOL_Unique2: #REF!
Name EOL_Unique3: #REF!
Name Fleet_data: #REF!
Name Footprint_Unique_Name: #REF!
Name FPXC: #REF!
Name Frozen: #REF!
Name FX_DB_lookups: #REF!
Name fxdb: #REF!
Name get_dieselgperkm: #REF!
Name get_gasgperkm: #REF!
Name Gjperton_jet: #REF!
Name In2_Air: #REF!
Name In2_Air_total: #REF!
Name In2_Boat: #REF!
Name In2_Boat_total: #REF!
Name In2_Rail: #REF!
Name In2_Rail_total: #REF!
Name IN2_Road_total: #REF!
Name ISR_Pack_SHC_List_LU: #REF!
Name ISR_SHC_List_LU: #REF!
Name kmper_nm: #REF!
Name line_type: #REF!
Name Material_Definition: #REF!
Name Material_LU: #REF!
Name PD_Lookup: #REF!
Name PD_Name: #REF!
Name Process_List: #REF!
Name Process_LU: #REF!
Name Rail_FC_Diesel: #REF!
Name Rail_Freight_Result_LU: #REF!
Name Rail_Frieght_Unique_Names: #REF!
Name Rail_type_DD: #REF!
Name Raw_Data_Unique: #REF!
Name Raw_data_unique_lu: #REF!
Name RDC_Results_LU: #REF!
Name RDC_Unique: #REF!
Name RDI_LU: #REF!

Sheet Scenario Selector
A1: Assumptions
F3: Scenarios
D4: 1 | F4: 1 | G4: 2 | H4: 3
B5: Assumptions | D5: Current | F5: Cocoa | G5: Coffee | H5: Vanilla
B6: Carbon price | D6: =_xlfn.XLOOKUP($D$4,$F$4:$H$4,F6:H6) -> 20 | F6: 20 | G6: 20 | H6: 20
B7: Project scale (ha) | D7: =_xlfn.XLOOKUP($D$4,$F$4:$H$4,F7:H7) -> 120000 | F7: 120000 | G7: 30000 | H7: 10000
B8: Carbon removal/ha/year | D8: =_xlfn.XLOOKUP($D$4,$F$4:$H$4,F8:H8) -> 2 | F8: 2 | G8: 2 | H8: 7.5
B9: Seedlings + labor/ha | D9: =_xlfn.XLOOKUP($D$4,$F$4:$H$4,F9:H9) -> 30 | F9: 30 | G9: 30 | H9: 400
B10: One-off setup costs/ha | D10: =_xlfn.XLOOKUP($D$4,$F$4:$H$4,F10:H10) -> 16 | F10: 16 | G10: 21 | H10: 22
B11: Running cost/ha/year | D11: =_xlfn.XLOOKUP($D$4,$F$4:$H$4,F11:H11) -> 15 | F11: 15 | G11: 15 | H11: 5
B12: Farmer carbon share | D12: =_xlfn.XLOOKUP($D$4,$F$4:$H$4,F12:H12) -> 0.2 | F12: 0.2 | G12: 0.2 | H12: 0.2
B13: First revenue year | D13: =_xlfn.XLOOKUP($D$4,$F$4:$H$4,F13:H13) -> 5 | F13: 5 | G13: 5 | H13: 5
B14: Trees per hectare | D14: =_xlfn.XLOOKUP($D$4,$F$4:$H$4,F14:H14) -> 30 | F14: 30 | G14: 30 | H14: n/a
B16: Total Trees | D16: =IF(ISERROR(D7*D14),"n/a",D7*D14) -> 3600000 | E16: calculated
B17: Farmers | D17: =+D7/D18 -> 60000 | E17: implied
B18: Hectares per farmer | D18: 2 | E18: assumed
D21: Costs
A22: Year | B22: Credits | C22: Revenue | D22: Planting | E22: Maintenance | F22: Farmer share | G22: Total | H22: Net cash | I22: IRR | J22: Cum. Cash
A23: 0 | D23: =-+D7*(D9+D10) -> -5520000 | G23: =+D23+E23+F23 -> -5520000 | H23: =+C23+G23 -> -5520000 | I23: =IF(ISERROR(IRR(H$23:H23)), "n/a",IRR(H$23:H23)) -> n/a | J23: =+H23 -> -5520000
A24: 1 | E24: =-D7*D11 -> -1800000 | F24: =+C24*$D$12 -> 0 | G24: =+D24+E24+F24 -> -1800000 | H24: =+C24+G24 -> -1800000 | I24: =IF(ISERROR(IRR(H$23:H24)), "n/a",IRR(H$23:H24)) -> n/a | J24: =+J23+H24 -> -7320000
A25: 2 | E25: =+E24 -> -1800000 | F25: =+C25*$D$12 -> 0 | G25: =+D25+E25+F25 -> -1800000 | H25: =+C25+G25 -> -1800000 | I25: =IF(ISERROR(IRR(H$23:H25)), "n/a",IRR(H$23:H25)) -> n/a | J25: =+J24+H25 -> -9120000
A26: 3 | E26: =+E25 -> -1800000 | F26: =+C26*$D$12 -> 0 | G26: =+D26+E26+F26 -> -1800000 | H26: =+C26+G26 -> -1800000 | I26: =IF(ISERROR(IRR(H$23:H26)), "n/a",IRR(H$23:H26)) -> n/a | J26: =+J25+H26 -> -10920000
A27: 4 | E27: =+E26 -> -1800000 | F27: =+C27*$D$12 -> 0 | G27: =+D27+E27+F27 -> -1800000 | H27: =+C27+G27 -> -1800000 | I27: =IF(ISERROR(IRR(H$23:H27)), "n/a",IRR(H$23:H27)) -> n/a | J27: =+J26+H27 -> -12720000
A28: 5 | B28: =$D$7*$D$8 -> 240000 | C28: =+$B$28*$D$6 -> 4800000 | E28: =+E27 -> -1800000 | F28: =-C28*$D$12 -> -960000 | G28: =+D28+E28+F28 -> -2760000 | H28: =+C28+G28 -> 2040000 | I28: =IF(ISERROR(IRR(H$23:H28)), "n/a",IRR(H$23:H28)) -> -0.47723292 | J28: =+J27+H28 -> -10680000
A29: 6 | B29: =+B28 -> 240000 | C29: =+C28 -> 4800000 | E29: =+E28 -> -1800000 | F29: =+F28 -> -960000 | G29: =+D29+E29+F29 -> -2760000 | H29: =+C29+G29 -> 2040000 | I29: =IF(ISERROR(IRR(H$23:H29)), "n/a",IRR(H$23:H29)) -> -0.26067096 | J29: =+J28+H29 -> -8640000
A30: 7 | B30: =+B29 -> 240000 | C30: =+C29 -> 4800000 | E30: =+E29 -> -1800000 | F30: =+F29 -> -960000 | G30: =+D30+E30+F30 -> -2760000 | H30: =+C30+G30 -> 2040000 | I30: =IF(ISERROR(IRR(H$23:H30)), "n/a",IRR(H$23:H30)) -> -0.15165554 | J30: =+J29+H30 -> -6600000
A31: 8 | B31: =+B30 -> 240000 | C31: =+C30 -> 4800000 | E31: =+E30 -> -1800000 | F31: =+F30 -> -960000 | G31: =+D31+E31+F31 -> -2760000 | H31: =+C31+G31 -> 2040000 | I31: =IF(ISERROR(IRR(H$23:H31)), "n/a",IRR(H$23:H31)) -> -0.084330255 | J31: =+J30+H31 -> -4560000
A32: 9 | B32: =+B31 -> 240000 | C32: =+C31 -> 4800000 | E32: =+E31 -> -1800000 | F32: =+F31 -> -960000 | G32: =+D32+E32+F32 -> -2760000 | H32: =+C32+G32 -> 2040000 | I32: =IF(ISERROR(IRR(H$23:H32)), "n/a",IRR(H$23:H32)) -> -0.038797614 | J32: =+J31+H32 -> -2520000
A33: 10 | B33: =+B32 -> 240000 | C33: =+C32 -> 4800000 | E33: =+E32 -> -1800000 | F33: =+F32 -> -960000 | G33: =+D33+E33+F33 -> -2760000 | H33: =+C33+G33 -> 2040000 | I33: =IF(ISERROR(IRR(H$23:H33)), "n/a",IRR(H$23:H33)) -> -0.0062994661 | J33: =+J32+H33 -> -480000
A34: 11 | B34: =+B33 -> 240000 | C34: =+C33 -> 4800000 | E34: =+E33 -> -1800000 | F34: =+F33 -> -960000 | G34: =+D34+E34+F34 -> -2760000 | H34: =+C34+G34 -> 2040000 | I34: =IF(ISERROR(IRR(H$23:H34)), "n/a",IRR(H$23:H34)) -> 0.017765699 | J34: =+J33+H34 -> 1560000
A35: 12 | B35: =+B34 -> 240000 | C35: =+C34 -> 4800000 | E35: =+E34 -> -1800000 | F35: =+F34 -> -960000 | G35: =+D35+E35+F35 -> -2760000 | H35: =+C35+G35 -> 2040000 | I35: =IF(ISERROR(IRR(H$23:H35)), "n/a",IRR(H$23:H35)) -> 0.03607945 | J35: =+J34+H35 -> 3600000
A36: 13 | B36: =+B35 -> 240000 | C36: =+C35 -> 4800000 | E36: =+E35 -> -1800000 | F36: =+F35 -> -960000 | G36: =+D36+E36+F36 -> -2760000 | H36: =+C36+G36 -> 2040000 | I36: =IF(ISERROR(IRR(H$23:H36)), "n/a",IRR(H$23:H36)) -> 0.050316278 | J36: =+J35+H36 -> 5640000
A37: 14 | B37: =+B36 -> 240000 | C37: =+C36 -> 4800000 | E37: =+E36 -> -1800000 | F37: =+F36 -> -960000 | G37: =+D37+E37+F37 -> -2760000 | H37: =+C37+G37 -> 2040000 | I37: =IF(ISERROR(IRR(H$23:H37)), "n/a",IRR(H$23:H37)) -> 0.061575548 | J37: =+J36+H37 -> 7680000
A38: 15 | B38: =+B37 -> 240000 | C38: =+C37 -> 4800000 | E38: =+E37 -> -1800000 | F38: =+F37 -> -960000 | G38: =+D38+E38+F38 -> -2760000 | H38: =+C38+G38 -> 2040000 | I38: =IF(ISERROR(IRR(H$23:H38)), "n/a",IRR(H$23:H38)) -> 0.070607362 | J38: =+J37+H38 -> 9720000
A39: 16 | B39: =+B38 -> 240000 | C39: =+C38 -> 4800000 | E39: =+E38 -> -1800000 | F39: =+F38 -> -960000 | G39: =+D39+E39+F39 -> -2760000 | H39: =+C39+G39 -> 2040000 | I39: =IF(ISERROR(IRR(H$23:H39)), "n/a",IRR(H$23:H39)) -> 0.077939515 | J39: =+J38+H39 -> 11760000
A40: 17 | B40: =+B39 -> 240000 | C40: =+C39 -> 4800000 | E40: =+E39 -> -1800000 | F40: =+F39 -> -960000 | G40: =+D40+E40+F40 -> -2760000 | H40: =+C40+G40 -> 2040000 | I40: =IF(ISERROR(IRR(H$23:H40)), "n/a",IRR(H$23:H40)) -> 0.083952915 | J40: =+J39+H40 -> 13800000
... A43: 20 | B43: =+B42 -> 240000 | C43: =+C42 -> 4800000 | E43: =+E42 -> -1800000 | F43: =+F42 -> -960000 | G43: =+D43+E43+F43 -> -2760000 | H43: =+C43+G43 -> 2040000 | I43: =IF(ISERROR(IRR(H$23:H43)), "n/a",IRR(H$23:H43)) -> 0.096559025 | J43: =+J42+H43 -> 19920000
A44: Total | B44: =SUM(B23:B43) -> 3840000 | C44: =SUM(C23:C43) -> 76800000 | D44: =SUM(D23:D43) -> -5520000 | E44: =SUM(E23:E43) -> -36000000 | F44: =SUM(F23:F43) -> -15360000 | G44: =SUM(G23:G43) -> -56880000 | H44: =SUM(H23:H43) -> 19920000

Sheet Scenario Comparison
A1: Side-by-Side Agroforestry Scenario Comparison
A3: Metric | B3: =+'Scenario Selector'!F5 -> Cocoa | C3: =+'Scenario Selector'!G5 -> Coffee | D3: =+'Scenario Selector'!H5 -> Vanilla
A4: Project scale (ha) | B4: ='Scenario Selector'!F7 -> 120000 | C4: ='Scenario Selector'!G7 -> 30000 | D4: ='Scenario Selector'!H7 -> 10000
A5: Carbon removal/ha/year | B5: ='Scenario Selector'!F8 -> 2 | C5: ='Scenario Selector'!G8 -> 2 | D5: ='Scenario Selector'!H8 -> 7.5
A6: Carbon price | B6: ='Scenario Selector'!F6 -> 20 | C6: ='Scenario Selector'!G6 -> 20 | D6: ='Scenario Selector'!H6 -> 20
A7: Initial planting cost/ha | B7: ='Scenario Selector'!F9 -> 30 | C7: ='Scenario Selector'!G9 -> 30 | D7: ='Scenario Selector'!H9 -> 400
A8: One-off setup costs/ha | B8: ='Scenario Selector'!F10 -> 16 | C8: ='Scenario Selector'!G10 -> 21 | D8: ='Scenario Selector'!H10 -> 22
A9: Running cost/ha/year | B9: ='Scenario Selector'!F11 -> 15 | C9: ='Scenario Selector'!G11 -> 15 | D9: ='Scenario Selector'!H11 -> 5
A10: Farmer carbon share | B10: ='Scenario Selector'!F12 -> 0.2 | C10: ='Scenario Selector'!G12 -> 0.2 | D10: ='Scenario Selector'!H12 -> 0.2
A11: Annual credits | B11: =B4*B5 -> 240000 | C11: =C4*C5 -> 60000 | D11: =D4*D5 -> 75000
A12: Annual revenue | B12: =B11*B6 -> 4800000 | C12: =C11*C6 -> 1200000 | D12: =D11*D6 -> 1500000
A13: Initial planting cost | B13: =B4*(B7+B8) -> 5520000 | C13: =C4*(C7+C8) -> 1530000 | D13: =D4*(D7+D8) -> 4220000
A14: Annual operating cost | B14: =B4*B9 -> 1800000 | C14: =C4*C9 -> 450000 | D14: =D4*D9 -> 50000
A15: Annual farmer share | B15: =B12*B10 -> 960000 | C15: =C12*C10 -> 240000 | D15: =D12*D10 -> 300000
A17: IRR | B17: =IRR(B22:B42) -> 0.096559025 | C17: =IRR(C22:C42) -> 0.09058781 | D17: =IRR(D22:D42) -> 0.13732337
A19: Simplified Annual Net Cash Flow Comparison
A21: Metric | B21: Cocoa shade trees | C21: Coffee shade trees | D21: Vanilla agroforestry
A22: 0 | B22: =-B13 -> -5520000 | C22: =-C13 -> -1530000 | D22: =-D13 -> -4220000
A23: 1 | B23: =-B$14 -> -1800000 | C23: =-C$14 -> -450000 | D23: =-D$14 -> -50000
A24: 2 | B24: =-B$14 -> -1800000 | C24: =-C$14 -> -450000 | D24: =-D$14 -> -50000
A25: 3 | B25: =-B$14 -> -1800000 | C25: =-C$14 -> -450000 | D25: =-D$14 -> -50000
A26: 4 | B26: =-B$14 -> -1800000 | C26: =-C$14 -> -450000 | D26: =-D$14 -> -50000
A27: 5 | B27: =+B$12-B$14-B$15 -> 2040000 | C27: =+C$12-C$14-C$15 -> 510000 | D27: =+D$12-D$14-D$15 -> 1150000
A28: 6 | B28: =+B$12-B$14-B$15 -> 2040000 | C28: =+C$12-C$14-C$15 -> 510000 | D28: =+D$12-D$14-D$15 -> 1150000
A29: 7 | B29: =+B$12-B$14-B$15 -> 2040000 | C29: =+C$12-C$14-C$15 -> 510000 | D29: =+D$12-D$14-D$15 -> 1150000
A30: 8 | B30: =+B$12-B$14-B$15 -> 2040000 | C30: =+C$12-C$14-C$15 -> 510000 | D30: =+D$12-D$14-D$15 -> 1150000
A31: 9 | B31: =+B$12-B$14-B$15 -> 2040000 | C31: =+C$12-C$14-C$15 -> 510000 | D31: =+D$12-D$14-D$15 -> 1150000
A32: 10 | B32: =+B$12-B$14-B$15 -> 2040000 | C32: =+C$12-C$14-C$15 -> 510000 | D32: =+D$12-D$14-D$15 -> 1150000
A33: 11 | B33: =+B$12-B$14-B$15 -> 2040000 | C33: =+C$12-C$14-C$15 -> 510000 | D33: =+D$12-D$14-D$15 -> 1150000
A34: 12 | B34: =+B$12-B$14-B$15 -> 2040000 | C34: =+C$12-C$14-C$15 -> 510000 | D34: =+D$12-D$14-D$15 -> 1150000
A35: 13 | B35: =+B$12-B$14-B$15 -> 2040000 | C35: =+C$12-C$14-C$15 -> 510000 | D35: =+D$12-D$14-D$15 -> 1150000
A36: 14 | B36: =+B$12-B$14-B$15 -> 2040000 | C36: =+C$12-C$14-C$15 -> 510000 | D36: =+D$12-D$14-D$15 -> 1150000
A37: 15 | B37: =+B$12-B$14-B$15 -> 2040000 | C37: =+C$12-C$14-C$15 -> 510000 | D37: =+D$12-D$14-D$15 -> 1150000
A38: 16 | B38: =+B$12-B$14-B$15 -> 2040000 | C38: =+C$12-C$14-C$15 -> 510000 | D38: =+D$12-D$14-D$15 -> 1150000
... A42: 20 | B42: =+B$12-B$14-B$15 -> 2040000 | C42: =+C$12-C$14-C$15 -> 510000 | D42: =+D$12-D$14-D$15 -> 1150000

Sheet Payback Sensitivity
A1: Payback Sensitivity Tables – Commercial Payback
A3: Recovery multiple (1) | D3: 2
A5: =+'Scenario Selector'!$F$5 -> Cocoa
A7: Data table inputs: | F7: Data table calcs ($000s):
A8: Input hectares | D8: 120000 | F8: Initial setup cost | L8: =+F11 -> Total Initial setup cost | O8: =+J11 -> 5520
A9: Input carbon price | D9: 20 | F9: Seedlings + labor | J9: =+D13*D8/1000 -> 3600 | L9: =+$A$3 -> Recovery multiple (1) | O9: =+$D$3 -> 2
F10: One-off overhead | J10: =+D19*D14/1000 -> 1920 | L10: Commercial recovery | P10: =+O8*O9 -> 11040
A11: Scenario assmptions: | F11: ="Total "&$F$8 -> Total Initial setup cost | J11: =SUM(J9:J10) -> 5520 | L11: =+F16 -> Pre-revenue running cost | P11: =+J16 -> 7200
A12: Carbon removal/ha/year | D12: ='Scenario Selector'!$F$8 -> 2 | L12: Commercial recovery target | P12: =+P10+P11 -> 18240
A13: Seedlings + labor/ha | D13: ='Scenario Selector'!$F$9 -> 30
A14: One-off overhead/ha | D14: ='Scenario Selector'!$F$10 -> 16 | F14: Running cost/year | I14: =+D8*D15/1000 -> 1800
A15: Running cost/ha/year | D15: ='Scenario Selector'!$F$11 -> 15 | F15: Pre-revenue years | I15: =+D17-1 -> 4 | L15: =+F15 -> Pre-revenue years | O15: =+I15 -> 4
A16: Farmer carbon share | D16: ='Scenario Selector'!$F$12 -> 0.2 | F16: Pre-revenue running cost | J16: =+I14*I15 -> 7200 | L16: Additional years needed | O16: =+P12/J23 -> 8.9411765
A17: First revenue year | D17: ='Scenario Selector'!$F$13 -> 5 | L17: Commercial Payback | O17: =IF(J23<=0,"-",ROUNDUP(O15+O16,0)) -> 13
A19: Base hectares (2) | D19: 120000 | F19: Annual gross revenue | I19: =D8*D12*D9/1000 -> 4800 | L19: Report base case payback | O19: 13
F20: Investor/Developer share % | I20: =1-D16 -> 0.8 | L20: Report vs model | O20: =IF(ISNUMBER(O17),O17-O19,"n/a") -> 0
F21: Investor/Developer share | J21: =+I19*I20 -> 3840
F22: =+F14 -> Running cost/year | J22: =+I14 -> 1800
F23: Annual net cash flow | J23: =+J21-J22 -> 2040
F25: =O17 -> 13 | G25: 12000 | H25: 30000 | I25: 60000 | J25: 90000 | K25: 120000 | L25: 150000 | M25: 180000 | N25: 210000 | O25: 240000
F26: 2 | G26: - | H26: - | I26: - | J26: - | K26: - | L26: - | M26: - | N26: - | O26: -
F27: 5 | G27: - | H27: - | I27: - | J27: - | K27: - | L27: - | M27: - | N27: - | O27: -
F28: 10 | G28: 444 | H28: 252 | I28: 188 | J28: 167 | K28: 156 | L28: 150 | M28: 146 | N28: 143 | O28: 140
F29: 15 | G29: 53 | H29: 32 | I29: 25 | J29: 23 | K29: 21 | L29: 21 | M29: 20 | N29: 20 | O29: 20
F30: 20 | G30: 30 | H30: 19 | I30: 15 | J30: 14 | K30: 13 | L30: 13 | M30: 13 | N30: 13 | O30: 12
F31: 25 | G31: 22 | H31: 14 | I31: 12 | J31: 11 | K31: 11 | L31: 10 | M31: 10 | N31: 10 | O31: 10
F32: 30 | G32: 18 | H32: 12 | I32: 10 | J32: 9 | K32: 9 | L32: 9 | M32: 9 | N32: 9 | O32: 9
F33: 35 | G33: 15 | H33: 11 | I33: 9 | J33: 8 | K33: 8 | L33: 8 | M33: 8 | N33: 8 | O33: 8
F34: 40 | G34: 13 | H34: 10 | I34: 8 | J34: 8 | K34: 8 | L34: 7 | M34: 7 | N34: 7 | O34: 7
A37: -1 | B37: “An ROI of 2x on initial setup costs is assumed as representative of commercial expectations.” p. 46
A38: =+A37-1 -> -2 | B38: For overhead dilution. Overhead is calibrated to the base case scale. Matches "Input" hectares but needs to be entered separately.
A39: =+'Scenario Selector'!$G$5 -> Coffee
A41: Data table inputs: | F41: Data table calcs ($000s):
A42: Input hectares | D42: 30000 | F42: Initial setup cost | L42: =+F45 -> Total Initial setup cost | O42: =+J45 -> 1530
A43: Input carbon price | D43: 20 | F43: Seedlings + labor | J43: =+D47*D42/1000 -> 900 | L43: =+$A$3 -> Recovery multiple (1) | O43: =+$D$3 -> 2
F44: One-off overhead | J44: =+D53*D48/1000 -> 630 | L44: Commercial recovery | P44: =+O42*O43 -> 3060
A45: Scenario assmptions: | F45: ="Total "&$F$8 -> Total Initial setup cost | J45: =SUM(J43:J44) -> 1530 | L45: =+F50 -> Pre-revenue running cost | P45: =+J50 -> 1800
A46: Carbon removal/ha/year | D46: ='Scenario Selector'!$G$8 -> 2 | L46: Commercial recovery target | P46: =+P44+P45 -> 4860
A47: Seedlings + labor/ha | D47: ='Scenario Selector'!$G$9 -> 30
A48: One-off overhead/ha | D48: ='Scenario Selector'!$G$10 -> 21 | F48: Running cost/year | I48: =+D42*D49/1000 -> 450
...
